Workbook

Sheet Operational Income (2)
A1: ورودی های عملیاتی
A2: ردیف | D2: بهمن 1403 | E2: اسفند 1403 | H2: فروردین 1404 | K2: ماه 4 | N2: ماه 5 | Q2: ماه 6
D3: 30 | E3: 10 | F3: 20 | G3: 30 | H3: 10 | I3: 20 | J3: 30 | K3: 10 | L3: 20 | M3: 30 | N3: 10 | O3: 20 | P3: 30 | Q3: 10 | R3: 20 | S3: 30
A4: پروژه واحدهای 56 و 57 آبادان | B4: تعدیل 3 | C4: مبلغ ناخالص | D4: =47910729957 -> 47910729957
C5: بیمه (5%) | D5: =-(D4*0.05) -> -2.3955365e+09 | E5: =-(E4*0.05) -> 0 | F5: =-(F4*0.05) -> 0 | G5: =-(G4*0.05) -> 0 | H5: =-(H4*0.05) -> 0 | I5: =-(I4*0.05) -> 0 | J5: =-(J4*0.05) -> 0
C6: پیش دریافت (20%)
C7: حسن انجام کار (10%) | D7: =-(D4*0.1) -> -4.791073e+09 | E7: =-(E4*0.1) -> 0 | F7: =-(F4*0.1) -> 0 | G7: =-(G4*0.1) -> 0 | H7: =-(H4*0.1) -> 0 | I7: =-(I4*0.1) -> 0 | J7: =-(J4*0.1) -> 0
C8: سایر کسورات
C9: مبلغ خالص | D9: =D4+D5+D6+D7+D8 -> 4.072412e+10 | E9: =E4+E5+E6+E7+E8 -> 0 | F9: =F4+F5+F6+F7+F8 -> 0 | G9: =G4+G5+G6+G7+G8 -> 0 | H9: =H4+H5+H6+H7+H8 -> 0 | I9: =I4+I5+I6+I7+I8 -> 0 | J9: =J4+J5+J6+J7+J8 -> 0
C10: ارزش افزوده | D10: =D4*0.1 -> 4.791073e+09 | E10: =E4*0.1 -> 0 | F10: =F4*0.1 -> 0 | G10: =G4*0.1 -> 0 | H10: =H4*0.1 -> 0 | I10: =I4*0.1 -> 0 | J10: =J4*0.1 -> 0
A11: پروژه واحدهای 56 و 57 آبادان | B11: صورت وضعیت 11 (آذر) | C11: مبلغ ناخالص | D11: 157051629551
C12: بیمه (5%) | D12: =-(D11*0.05) -> -7.8525815e+09 | E12: =-(E11*0.05) -> 0 | F12: =-(F11*0.05) -> 0 | G12: =-(G11*0.05) -> 0 | H12: =-(H11*0.05) -> 0 | I12: =-(I11*0.05) -> 0 | J12: =-(J11*0.05) -> 0
C13: پیش دریافت (20%) | D13: =-(D11*0.2) -> -3.1410326e+10
C14: حسن انجام کار (10%) | D14: =-(D11*0.1) -> -1.5705163e+10 | E14: =-(E11*0.1) -> 0 | F14: =-(F11*0.1) -> 0 | G14: =-(G11*0.1) -> 0 | H14: =-(H11*0.1) -> 0 | I14: =-(I11*0.1) -> 0 | J14: =-(J11*0.1) -> 0
C15: سایر کسورات
C16: مبلغ خالص | D16: =D11+D12+D13+D14+D15 -> 1.0208356e+11 | E16: =E11+E12+E13+E14+E15 -> 0 | F16: =F11+F12+F13+F14+F15 -> 0 | G16: =G11+G12+G13+G14+G15 -> 0 | H16: =H11+H12+H13+H14+H15 -> 0 | I16: =I11+I12+I13+I14+I15 -> 0 | J16: =J11+J12+J13+J14+J15 -> 0
C17: ارزش افزوده | D17: =D11*0.1 -> 1.5705163e+10 | E17: =E11*0.1 -> 0 | F17: =F11*0.1 -> 0 | G17: =G11*0.1 -> 0 | H17: =H11*0.1 -> 0 | I17: =I11*0.1 -> 0 | J17: =J11*0.1 -> 0
A18: پروژه واحدهای 56 و 57 آبادان | B18: تعدیل 4 (ص و 10) | C18: مبلغ ناخالص | E18: 53475129273
C19: بیمه (5%) | D19: =-(D18*0.05) -> 0 | E19: =-(E18*0.05) -> -2.6737565e+09 | F19: =-(F18*0.05) -> 0 | G19: =-(G18*0.05) -> 0 | H19: =-(H18*0.05) -> 0 | I19: =-(I18*0.05) -> 0 | J19: =-(J18*0.05) -> 0
C20: پیش دریافت (20%)
C21: حسن انجام کار (10%) | D21: =-(D18*0.1) -> 0 | E21: =-(E18*0.1) -> -5.3475129e+09 | F21: =-(F18*0.1) -> 0 | G21: =-(G18*0.1) -> 0 | H21: =-(H18*0.1) -> 0 | I21: =-(I18*0.1) -> 0 | J21: =-(J18*0.1) -> 0
C22: سایر کسورات
C23: مبلغ خالص | D23: =D18+D19+D20+D21+D22 -> 0 | E23: =E18+E19+E20+E21+E22 -> 4.545386e+10 | F23: =F18+F19+F20+F21+F22 -> 0 | G23: =G18+G19+G20+G21+G22 -> 0 | H23: =H18+H19+H20+H21+H22 -> 0 | I23: =I18+I19+I20+I21+I22 -> 0 | J23: =J18+J19+J20+J21+J22 -> 0
C24: ارزش افزوده | D24: =D18*0.1 -> 0 | E24: =E18*0.1 -> 5.3475129e+09 | F24: =F18*0.1 -> 0 | G24: =G18*0.1 -> 0 | H24: =H18*0.1 -> 0 | I24: =I18*0.1 -> 0 | J24: =J18*0.1 -> 0
A25: پروژه واحدهای 56 و 57 آبادان | B25: تعدیل 5 (ص و 11) | C25: مبلغ ناخالص | E25: 44759714422
C26: بیمه (5%) | D26: =-(D25*0.05) -> 0 | E26: =-(E25*0.05) -> -2.2379857e+09 | F26: =-(F25*0.05) -> 0 | G26: =-(G25*0.05) -> 0 | H26: =-(H25*0.05) -> 0 | I26: =-(I25*0.05) -> 0 | J26: =-(J25*0.05) -> 0
C27: پیش دریافت (20%)
C28: حسن انجام کار (10%) | D28: =-(D25*0.1) -> 0 | E28: =-(E25*0.1) -> -4.4759714e+09 | F28: =-(F25*0.1) -> 0 | G28: =-(G25*0.1) -> 0 | H28: =-(H25*0.1) -> 0 | I28: =-(I25*0.1) -> 0 | J28: =-(J25*0.1) -> 0
C29: سایر کسورات
C30: مبلغ خالص | D30: =D25+D26+D27+D28+D29 -> 0 | E30: =E25+E26+E27+E28+E29 -> 3.8045757e+10 | F30: =F25+F26+F27+F28+F29 -> 0 | G30: =G25+G26+G27+G28+G29 -> 0 | H30: =H25+H26+H27+H28+H29 -> 0 | I30: =I25+I26+I27+I28+I29 -> 0 | J30: =J25+J26+J27+J28+J29 -> 0
C31: ارزش افزوده | D31: =D25*0.1 -> 0 | E31: =E25*0.1 -> 4.4759714e+09 | F31: =F25*0.1 -> 0 | G31: =G25*0.1 -> 0 | H31: =H25*0.1 -> 0 | I31: =I25*0.1 -> 0 | J31: =J25*0.1 -> 0
A32: پروژه واحدهای 56 و 57 آبادان | B32: صورت وضعیت 12 (دی) | C32: مبلغ ناخالص | E32: 241312500000
C33: بیمه (5%) | D33: =-(D32*0.05) -> 0 | E33: =-(E32*0.05) -> -12065625000 | F33: =-(F32*0.05) -> 0 | G33: =-(G32*0.05) -> 0 | H33: =-(H32*0.05) -> 0 | I33: =-(I32*0.05) -> 0 | J33: =-(J32*0.05) -> 0
C34: پیش دریافت (20%) | D34: =-(D32*0.2) -> 0 | E34: =-(E32*0.2) -> -48262500000 | F34: =-(F32*0.2) -> 0 | G34: =-(G32*0.2) -> 0 | H34: =-(H32*0.2) -> 0 | I34: =-(I32*0.2) -> 0 | J34: =-(J32*0.2) -> 0
C35: حسن انجام کار (10%) | D35: =-(D32*0.1) -> 0 | E35: =-(E32*0.1) -> -24131250000 | F35: =-(F32*0.1) -> 0 | G35: =-(G32*0.1) -> 0 | H35: =-(H32*0.1) -> 0 | I35: =-(I32*0.1) -> 0 | J35: =-(J32*0.1) -> 0
C36: سایر کسورات
C37: مبلغ خالص | D37: =D32+D33+D34+D35+D36 -> 0 | E37: =E32+E33+E34+E35+E36 -> 156853125000 | F37: =F32+F33+F34+F35+F36 -> 0 | G37: =G32+G33+G34+G35+G36 -> 0 | H37: =H32+H33+H34+H35+H36 -> 0 | I37: =I32+I33+I34+I35+I36 -> 0 | J37: =J32+J33+J34+J35+J36 -> 0
C38: ارزش افزوده | D38: =D32*0.1 -> 0 | E38: =E32*0.1 -> 24131250000 | F38: =F32*0.1 -> 0 | G38: =G32*0.1 -> 0 | H38: =H32*0.1 -> 0 | I38: =I32*0.1 -> 0 | J38: =J32*0.1 -> 0
A39: پروژه واحدهای 56 و 57 آبادان | B39: تعدیل 6 (ص و 12) | C39: مبلغ ناخالص | F39: 96525000000
C40: بیمه (5%) | D40: =-(D39*0.05) -> 0 | E40: =-(E39*0.05) -> 0 | F40: =-(F39*0.05) -> -4826250000 | G40: =-(G39*0.05) -> 0 | H40: =-(H39*0.05) -> 0 | I40: =-(I39*0.05) -> 0 | J40: =-(J39*0.05) -> 0
...

Sheet خروجی 
A1: راه اندازی آبادان | I1: مهندسی صومعه سرا | P1: دفتر مرکزی
A2: شرح | B2: بهمن 1403 | C2: اسفند 1403 | F2: فروردین 1404 | I2: بهمن 1403 | J2: اسفند 1403 | M2: فروردین 1404 | P2: بهمن 1403 | Q2: اسفند 1403 | T2: فروردین 1404
B3: 30 | C3: 10 | D3: 20 | E3: 30 | F3: 10 | G3: 20 | H3: 30 | I3: 30 | J3: 10 | K3: 20 | L3: 30 | M3: 10 | N3: 20 | O3: 30 | P3: 30 | Q3: 10 | R3: 20 | S3: 30 | T3: 10 | U3: 20 | V3: 30
A4: حقوق | B4: 0 | C4: 62000000000 | F4: 62000000000 | I4: 3500000000 | L4: 3500000000 | P4: 6500000000 | S4: 6500000000
A5: بیمه | B5: 5400000000 | E5: 5400000000 | H5: 7400000000 | I5: 800000000 | L5: 800000000 | O5: 1000000000 | P5: 180000000 | S5: 180000000 | V5: 300000000
A6: مالیات | B6: =15210047498+2750000000 -> 17960047498 | C6: 7605023749 | E6: 2750000000 | H6: 4000000000 | I6: 400000000 | L6: 400000000 | O6: 600000000 | P6: 130000000 | S6: 130000000 | V6: 130000000
A7: مالیات معوق | B7: 7780000000 | I7: 720000000 | P7: 2010000000
A8: اثاثه | H8: 250000000 | V8: 550000000
A9: اجاره | C9: 1175000000 | F9: 1175000000 | J9: 280000000 | M9: 280000000 | Q9: 221000000 | T9: 221000000
A10: هدایا | C10: 5000000000 | D10: 5000000000 | H10: 500000000
A11: عیدی | D11: 55000000000 | I11: 3500000000 | P11: 6500000000
A12: تنخواه | B12: 1500000000 | C12: 1500000000 | D12: 1500000000 | E12: 2500000000 | F12: 2200000000 | H12: 1300000000 | P12: 1000000000 | Q12: 1000000000 | R12: 6000000000 | V12: 2000000000
A13: سایر | D13: 90000000000 | P13: =1500000000+1500000000 -> 3000000000 | S13: 3500000000
A14: جمع | B14: =SUM(B4:B13) -> 32640047498 | C14: =SUM(C4:C13) -> 77280023749 | D14: =SUM(D4:D13) -> 151500000000 | E14: =SUM(E4:E13) -> 10650000000 | F14: =SUM(F4:F13) -> 65375000000 | G14: =SUM(G4:G13) -> 0 | H14: =SUM(H4:H13) -> 13450000000 | I14: =SUM(I4:I13) -> 8920000000 | ... V14: =SUM(V4:V13) -> 2980000000

Sheet Operational Income
A2: شرح | C2: بهمن 1403 | E2: اسفند 1403 | K2: فروردین 1404
C3: 30 | E3: 10 | H3: 20 | J3: 30 | K3: 10 | L3: 20 | N3: 30
C4: آبادان | D4: صومعه سرا- مهندسی تفصیلی | E4: صومعه سرا- مهندسی تفصیلی | F4: صومعه سرا- مهندسی خرید | G4: آبادان | H4: صومعه سرا- مهندسی تفصیلی | I4: آبادان | J4: آبادان | L4: صومعه سرا- مهندسی تفصیلی | M4: آبادان
A5: محاسبه خالص ورودی های عملیاتی | B5: مبلغ ناخالص | C5: =47910729957+157051629551 -> 204962359508 | D5: =7247861000+4163917000+2637180750+1518740250+4182407750 -> 19750106750 | E5: =3717640250+4528734500+2529734500 -> 10776109250 | F5: =8750129926 -> 8750129926 | G5: =53475129273+44759714422+169000000000 -> 267234843695 | H5: 800000000 | I5: =96525000000+169000000000 -> 265525000000 | J5: =0.4*169000000000 -> 67600000000 | L5: 3570000000 | M5: 220350000000
B6: بیمه (5%) | C6: =-(C5*0.05) -> -1.0248118e+10 | D6: =-(D5*0.05) -> -9.8750534e+08 | E6: =-(E5*0.05) -> -5.3880546e+08 | F6: =-(F5*0.05) -> -4.375065e+08 | G6: =-(G5*0.05) -> -1.3361742e+10 | H6: =-(H5*0.05) -> -40000000 | I6: =-(I5*0.05) -> -13276250000 | J6: =-(J5*0.05) -> -3380000000 | ... N6: =-(N5*0.05) -> 0
B7: پیش دریافت | C7: -31410325910 | D7: =-0.3*D5 -> -5925032025 | E7: =-0.3*E5 -> -3232832775 | H7: =-0.3*H5 -> -240000000 | L7: =-0.3*L5 -> -1071000000
B8: حسن انجام کار | C8: =-(C5*0.1) -> -2.0496236e+10 | D8: =-(D5*0.1) -> -1975010675 | E8: =-(E5*0.1) -> -1077610925 | F8: =-(F5*0.1) -> -8.7501299e+08 | G8: =-(G5*0.1) -> -2.6723484e+10 | H8: =-(H5*0.1) -> -80000000 | I8: =-(I5*0.1) -> -26552500000 | J8: =-(J5*0.1) -> -6760000000 | ... N8: =-(N5*0.1) -> 0
B9: سایر کسورات
B10: مبلغ خالص | C10: =C5+C6+C7+C8+C9 -> 1.4280768e+11 | D10: =D5+D6+D7+D8+D9 -> 1.0862559e+10 | E10: =E5+E6+E7+E8+E9 -> 5.9268601e+09 | F10: =F5+F6+F7+F8+F9 -> 7.4376104e+09 | G10: =G5+G6+G7+G8+G9 -> 2.2714962e+11 | H10: =H5+H6+H7+H8+H9 -> 440000000 | I10: =I5+I6+I7+I8+I9 -> 225696250000 | J10: =J5+J6+J7+J8+J9 -> 57460000000 | K10: =K5+K6+K7+K8+Z8 -> 0 | L10: =L5+L6+L7+L8+L9 -> 1963500000 | M10: =M5+M6+M7+M8+M9 -> 187297500000 | N10: =N5+N6+N7+N8+N9 -> 0
B11: ارزش افزوده | C11: =C5*0.1 -> 2.0496236e+10 | D11: =D5*0.1 -> 1975010675 | E11: =E5*0.1 -> 1077610925 | F11: =F5*0.1 -> 8.7501299e+08 | G11: =G5*0.1 -> 2.6723484e+10 | H11: =H5*0.1 -> 80000000 | I11: =I5*0.1 -> 26552500000 | J11: =J5*0.1 -> 6760000000 | ... N11: =N5*0.1 -> 0

Sheet Cash Flow
A1: جریان وجوه نقد ایده تدبیر مهام
A2: ردیف | B2: شرح | F2: بهمن 1403 | G2: اسفند 1403 | J2: فروردین 1404
F3: 30 | G3: 10 | H3: 20 | I3: 30 | J3: 10 | K3: 20 | L3: 30
A4: مانده پایان دوره | F4: =F5+F6-F26 -> 1.0218174e+11 | G4: =G5+G6-G26 -> 2.889148e+11 | H4: =H5+H6-H26 -> 3.5755105e+11 | I4: =I5+I6-I26 -> 3.8935105e+11 | J4: =J5+J6-J26 -> 3.2347505e+11 | K4: =K5+K6-K26 -> 5.1273605e+11 | L4: =L5+L6-L26 -> 4.9725605e+11
A5: 1 | C5: مانده اول دوره | F5: 9391546552 | G5: =F4 -> 1.0218174e+11 | H5: =G4 -> 2.889148e+11 | I5: =H4 -> 3.5755105e+11 | J5: =I4 -> 3.8935105e+11 | K5: =J4 -> 3.2347505e+11 | L5: =K4 -> 5.1273605e+11
A6: 2 | B6: جریان های نقدی ورودی | F6: =F7+F18 -> 1.7614149e+11 | G6: =G7+G18 -> 2.931902e+11 | H6: =H7+H18 -> 252768750000 | I6: =I7+I18 -> 64220000000 | J6: =J7+J18 -> 0 | K6: =K7+K18 -> 211653000000 | L6: =L7+L18 -> 0
A7: 2.1 | C7: ورودی عملیاتی | F7: =SUM(F8:F17) -> 1.5367024e+11 | G7: =SUM(G8:G17) -> 2.4051409e+11 | H7: =SUM(H8:H17) -> 226136250000 | I7: =SUM(I8:I17) -> 57460000000 | J7: =SUM(J8:J17) -> 0 | K7: =SUM(K8:K17) -> 189261000000 | L7: =SUM(L8:L17) -> 0
A8: 2.1.1 | D8: پیش دریافت قرارداد
A9: 2.1.2 | D9: علی الحساب دریافتی
A10: 2.1.3 | D10: خدمات مهندسی | F10: ='Operational Income'!D10 -> 1.0862559e+10 | G10: ='Operational Income'!E10+'Operational Income'!F10 -> 1.3364471e+10 | H10: ='Operational Income'!H10 -> 440000000 | K10: ='Operational Income'!L10 -> 1963500000
A11: 2.1.4 | D11: تامین کالا | V11: ='Operational Income'!I10 -> 225696250000
A12: 2.1.5 | D12: راه اندازی | F12: ='Operational Income'!C10 -> 1.4280768e+11 | G12: ='Operational Income'!G10 -> 2.2714962e+11 | H12: ='Operational Income'!I10 -> 225696250000 | I12: ='Operational Income'!J10 -> 57460000000 | J12: ='Operational Income'!K10+'Operational Income'!K11 -> 0 | K12: ='Operational Income'!M10 -> 187297500000 | L12: ='Operational Income'!N10 -> 0
A13: 2.1.6 | D13: خدمات آموزش
A14: 2.1.7 | D14: آزادسازی سپرده بیمه
A15: 2.1.8 | D15: آزادسازی سپرده حسن انجام کار
A16: 2.1.9 | D16: برگشت سپرده نقدی ضمانت نامه
A17: 2.1.10 | D17: سایر دریافت های عملیاتی
A18: 2.2 | C18: ورودی غیرعملیاتی | F18: =SUM(F19:F25) -> 2.2471247e+10 | G18: =SUM(G19:G25) -> 5.2676108e+10 | H18: =SUM(H19:H25) -> 26632500000 | I18: =SUM(I19:I25) -> 6760000000 | J18: =SUM(J19:J25) -> 0 | K18: =SUM(K19:K25) -> 22392000000 | L18: =SUM(L19:L25) -> 0
A19: 2.2.1 | D19: تسهیلات بانکی
A20: 2.2.2 | D20: سود سپرده
A21: 2.2.3 | D21: افزایش سرمایه (آورده نقدی)
A22: 2.2.4 | D22: سود حاصل از سرمایه گذاری
A23: 2.2.5 | D23: فروش دارایی ها | G23: 24000000000
A24: 2.2.6 | D24: ارزش افزوده | F24: ='Operational Income'!D11+'Operational Income'!C11 -> 2.2471247e+10 | G24: ='Operational Income'!E11+'Operational Income'!F11+'Operational Income'!G11 -> 2.8676108e+10 | H24: ='Operational Income'!H11+'Operational Income'!I11 -> 26632500000 | I24: ='Operational Income'!J11 -> 6760000000 | K24: ='Operational Income'!L11+'Operational Income'!M11 -> 22392000000
A25: 2.2.6 | D25: سایر دریافت های غیرعملیاتی
A26: 3 | B26: جریان های نقدی خروجی | F26: =F27+F36 -> 8.3351294e+10 | G26: =G27+G36 -> 1.0645713e+11 | H26: =H27+H36 -> 184132500000 | I26: =I27+I36 -> 32420000000 | J26: =J27+J36 -> 65876000000 | K26: =K27+K36 -> 22392000000 | L26: =L27+L36 -> 15480000000
A27: 3.1 | C27: خروجی های عملیاتی | F27: =SUM(F28:F35) -> 41560047498 | G27: =SUM(G28:G35) -> 77560023749 | H27: =SUM(H28:H35) -> 151500000000 | I27: =SUM(I28:I35) -> 15350000000 | J27: =SUM(J28:J35) -> 65655000000 | K27: =SUM(K28:K35) -> 0 | L27: =SUM(L28:L35) -> 15050000000
A28: 3.1.1 | D28: هزینه خدمات مهندسی | F28: ='خروجی '!I14 -> 8920000000 | G28: ='خروجی '!J14 -> 280000000 | H28: ='خروجی '!K14 -> 0 | I28: ='خروجی '!L14 -> 4700000000 | J28: ='خروجی '!M14 -> 280000000 | K28: ='خروجی '!N14 -> 0 | L28: ='خروجی '!O14 -> 1600000000
A29: 3.1.2 | D29: هزینه تامین کالا
A30: 3.1.3 | D30: هزینه راه اندازی | F30: ='خروجی '!B14 -> 32640047498 | G30: ='خروجی '!C14 -> 77280023749 | H30: ='خروجی '!D14 -> 151500000000 | I30: ='خروجی '!E14 -> 10650000000 | J30: ='خروجی '!F14 -> 65375000000 | K30: ='خروجی '!G14 -> 0 | L30: ='خروجی '!H14 -> 13450000000
A31: 3.1.4 | D31: هزینه خدمات آموزش
A32: 3.1.5 | D32: سپرده نقدی ضمانت نامه
A33: 3.1.6 | D33: کارمزد بانکی
A34: 3.1.7 | D34: پرداخت علی الحساب و پیش پرداخت
A35: 3.1.8 | D35: سایر پرداخت های عملیاتی
A36: 3.2 | C36: خروجی های غیر عملیاتی | F36: =SUM(F37:F44) -> 4.1791247e+10 | G36: =SUM(G37:G44) -> 2.8897108e+10 | H36: =SUM(H37:H44) -> 32632500000 | I36: =SUM(I37:I44) -> 17070000000 | J36: =SUM(J37:J44) -> 221000000 | K36: =SUM(K37:K44) -> 22392000000 | L36: =SUM(L37:L44) -> 430000000
A37: 3.2.1 | D37: حقوق و دستمزد | F37: ='خروجی '!P4+'خروجی '!P5+'خروجی '!P6+'خروجی '!P7+'خروجی '!P11 -> 15320000000 | I37: ='خروجی '!S4+'خروجی '!S5+'خروجی '!S6 -> 6810000000 | L37: ='خروجی '!V5+'خروجی '!V6 -> 430000000
A38: 3.2.2 | D38: هزینه های اداری و تشکیلاتی
A39: 3.2.3 | D39: هزینه های توسعه بازار
A40: 3.2.4 | D40: اقساط تسهیلات دریافتی
...
